<?xml version="1.0"?>
<robot name="tegas">
    <link name="world"/>
    <link name="base_link">
        <visual>
            <origin xyz="-0.5 -0.5 0.0" rpy="0.0 0.0 0.0"/>
            <geometry>
                <mesh filename="package://lab8/mesh/basement.STL" scale="0.01 0.01 0.01"/>
            </geometry>
        </visual>
        <material>
            <color rgba="1.0 0.0 0.0 1.0"/>
        </material>
    </link>

    <link name="base_plate">
        <visual>
            <origin xyz="-0.39 -0.39 0.56" rpy="0.0 0.0 0.0"/>
            <geometry>
                <mesh filename="package://lab8/mesh/base_plate.STL" scale="0.01 0.01 0.01"/>
            </geometry>
        </visual>
        <material>
            <color rgba="0.0 1.0 0.0 1.0"/>
        </material>
    </link>

    <link name="forward_drive_arm">
        <visual>
            <origin xyz="-0.19 0.06 -0.08" rpy="0.0 -${1.57} ${1.57}"/>
            <geometry>
                <mesh filename="package://lab8/mesh/forward_drive_arm.STL" scale="0.01 0.01 0.01"/>
            </geometry>
        </visual>
        <material>
            <color rgba="0.0 0.0 1.0 1.0"/>
        </material>
    </link>

    <joint name="virtual_joint" type="fixed">
        <parent link ="world"/>
        <child link="base_link"/>
        <origin xyz="0.0 0.0 0.0" rpy="0.0 0.0 0.0"/>
    </joint>
    <joint name="joint_1" type="revolute">
        <parent link ="base_link"/>
        <child link="base_plate"/>
        <origin xyz="0.0 0.0 0.307" rpy="0.0 0.0 0.0"/>
        <axis xyz="0.0 0.0 1.0"/>
        <limit lower="-${1.57}" upper="${1.57}" effort="30" velocity="10"/>
    </joint>
    <joint name="joint_2" type="revolute">
        <parent link ="base_plate"/>
        <child link="forward_drive_arm"/>
        <origin xyz="0.0 0.0 0.0" rpy="0.0 0.0 0.0"/>
        <axis xyz="1.0 0.0 0.0"/>
        <limit lower="-${1.57}" upper="${1.57}" effort="30" velocity="10"/>
    </joint>

</robot>